<?xml version="1.0" ?>
<robot name="module_quadrotor">
  <baselink name="fc"/>
  <thrust_link name="thrust"/>
  <m_f_rate value="-0.011"/>
  <link name="root">
    <inertial>
      <origin rpy="0 0 0" xyz="0 0 0"/>
      <mass value="0.00001"/>
      <inertia ixx="0.000001" ixy="0.0" ixz="0.0" iyy="0.000001" iyz="0.0" izz="0.000002"/>
    </inertial>
  </link>
  <joint name="root_joint" type="fixed">
    <parent link="root"/>
    <child link="main_body"/>
    <origin rpy="0 0 0" xyz="0 0 0"/>
    <axis xyz="0 0 1"/>
  </joint>
  <link name="main_body">
    <inertial>
      <mass value="0.832"/>
      <origin rpy="0 0 0" xyz="0.002 0 0.026000000000000002"/>
      <inertia ixx="0.0030" ixy="0" ixz="0" iyy="0.0030" iyz="0" izz="0.0045"/>
    </inertial>
    <visual>
      <origin rpy="0 0 0" xyz="0 0 0"/>
      <geometry>
        <mesh filename="main_body_livox.stl"/>
      </geometry>
    </visual>
    <collision name="main_body">
      <origin rpy="0 0 0" xyz="0 0 0"/>
      <geometry>
        <mesh filename="main_body_livox.stl"/>
      </geometry>
    </collision>
  </link>
  <joint name="main_body2fc" type="fixed">
    <parent link="main_body"/>
    <child link="fc"/>
    <origin rpy="0 0 0" xyz="0 0 0"/>
  </joint>
  <link name="fc">
    <inertial>
      <mass value="00"/>
      <origin rpy="0 0 0" xyz="0 0 0"/>
      <inertia ixx="0.0" ixy="0.0" ixz="0.0" iyy="0.0" iyz="0.0" izz="0.0"/>
    </inertial>
  </link>
  <joint name="main_body2lidar_imu" type="fixed">
    <parent link="main_body"/>
    <child link="lidar_imu"/>
    <origin rpy="0 0 0" xyz="0.011 0.02329 0.04538"/>
  </joint>
  <link name="lidar_imu">
    <inertial>
      <mass value="00"/>
      <origin rpy="0 0 0" xyz="0 0 0"/>
      <inertia ixx="0.0" ixy="0.0" ixz="0.0" iyy="0.0" iyz="0.0" izz="0.0"/>
    </inertial>
  </link>
  <joint name="main_body2battery" type="fixed">
    <parent link="main_body"/>
    <child link="battery"/>
    <origin rpy="1.5707963267948966 0 0" xyz="0.0 0 -0.035"/>
  </joint>
  <link name="battery">
    <inertial>
      <mass value="0.188"/>
      <origin rpy="0 0 0" xyz="0 0 0"/>
      <inertia ixx="0.0002" ixy="0.0" ixz="0.0" iyy="0.0002" iyz="0.0" izz="0.0002"/>
    </inertial>
    <visual>
      <origin rpy="0 0 0" xyz="0 0 0"/>
      <geometry>
        <mesh filename="turnigy_3S_2200mAh.stl"/>
      </geometry>
    </visual>
    <collision name="battery">
      <origin rpy="0 0 0" xyz="0 0 0"/>
      <geometry>
        <mesh filename="turnigy_3S_2200mAh.stl"/>
      </geometry>
    </collision>
  </link>
  <joint name="rotor1" type="continuous">
    <limit effort="100.0" lower="0.0" upper="8.0" velocity="0.5"/>
    <parent link="main_body"/>
    <child link="thrust1"/>
    <origin rpy="0 0 0" xyz="-0.085 -0.085 0.026"/>
    <axis xyz="0 0 -1"/>
  </joint>
  <link name="thrust1">
    <inertial>
      <origin rpy="0 0 0" xyz="0 0 0"/>
      <mass value="0.0091"/>
      <inertia ixx="0.00000807" ixy="0.0" ixz="0.0" iyy="0.00000807" iyz="0.0" izz="0.00001612"/>
    </inertial>
    <visual>
      <origin rpy="0 0 0" xyz="0 0 0"/>
      <geometry>
        <mesh filename="prop_5inch.stl"/>
      </geometry>
    </visual>
    <collision name="thrust1">
      <origin rpy="0 0 0" xyz="0 0 0"/>
      <geometry>
        <mesh filename="prop_5inch.stl"/>
      </geometry>
    </collision>
  </link>
  <gazebo reference="main_body">
    <dampingFactor>0.00</dampingFactor>
  </gazebo>
  <joint name="rotor2" type="continuous">
    <limit effort="100.0" lower="0.0" upper="8.0" velocity="0.5"/>
    <parent link="main_body"/>
    <child link="thrust2"/>
    <origin rpy="0 0 0" xyz="0.085 -0.085 0.026"/>
    <axis xyz="0 0 1"/>
  </joint>
  <link name="thrust2">
    <inertial>
      <origin rpy="0 0 0" xyz="0 0 0"/>
      <mass value="0.0091"/>
      <inertia ixx="0.00000807" ixy="0.0" ixz="0.0" iyy="0.00000807" iyz="0.0" izz="0.00001612"/>
    </inertial>
    <visual>
      <origin rpy="0 0 0" xyz="0 0 0"/>
      <geometry>
        <mesh filename="prop_5inch.stl"/>
      </geometry>
    </visual>
    <collision name="thrust2">
      <origin rpy="0 0 0" xyz="0 0 0"/>
      <geometry>
        <mesh filename="prop_5inch.stl"/>
      </geometry>
    </collision>
  </link>
  <gazebo reference="main_body">
    <dampingFactor>0.00</dampingFactor>
  </gazebo>
  <joint name="rotor3" type="continuous">
    <limit effort="100.0" lower="0.0" upper="8.0" velocity="0.5"/>
    <parent link="main_body"/>
    <child link="thrust3"/>
    <origin rpy="0 0 0" xyz="0.085 0.085 0.026"/>
    <axis xyz="0 0 -1"/>
  </joint>
  <link name="thrust3">
    <inertial>
      <origin rpy="0 0 0" xyz="0 0 0"/>
      <mass value="0.0091"/>
      <inertia ixx="0.00000807" ixy="0.0" ixz="0.0" iyy="0.00000807" iyz="0.0" izz="0.00001612"/>
    </inertial>
    <visual>
      <origin rpy="0 0 0" xyz="0 0 0"/>
      <geometry>
        <mesh filename="prop_5inch.stl"/>
      </geometry>
    </visual>
    <collision name="thrust3">
      <origin rpy="0 0 0" xyz="0 0 0"/>
      <geometry>
        <mesh filename="prop_5inch.stl"/>
      </geometry>
    </collision>
  </link>
  <gazebo reference="main_body">
    <dampingFactor>0.00</dampingFactor>
  </gazebo>
  <joint name="rotor4" type="continuous">
    <limit effort="100.0" lower="0.0" upper="8.0" velocity="0.5"/>
    <parent link="main_body"/>
    <child link="thrust4"/>
    <origin rpy="0 0 0" xyz="-0.085 0.085 0.026"/>
    <axis xyz="0 0 1"/>
  </joint>
  <link name="thrust4">
    <inertial>
      <origin rpy="0 0 0" xyz="0 0 0"/>
      <mass value="0.0091"/>
      <inertia ixx="0.00000807" ixy="0.0" ixz="0.0" iyy="0.00000807" iyz="0.0" izz="0.00001612"/>
    </inertial>
    <visual>
      <origin rpy="0 0 0" xyz="0 0 0"/>
      <geometry>
        <mesh filename="prop_5inch.stl"/>
      </geometry>
    </visual>
    <collision name="thrust4">
      <origin rpy="0 0 0" xyz="0 0 0"/>
      <geometry>
        <mesh filename="prop_5inch.stl"/>
      </geometry>
    </collision>
  </link>
  <gazebo reference="main_body">
    <dampingFactor>0.00</dampingFactor>
  </gazebo>
  <mujoco>
    <compiler balanceinertia="true"/>
    <option/>
  </mujoco>
</robot>
