<?xml version="1.0" ?>
<robot name="hydrus_xi">
  <baselink name="fc"/>
  <thrust_link name="thrust"/>
  <m_f_rate value="-0.0182"/>
    #### dummy root link for KDL ####
  <link name="root">
    <inertial>
      <origin rpy="0 0 0" xyz="0 0 0"/>
      <mass value="0.00001"/>
      <inertia ixx="0.000001" ixy="0.0" ixz="0.0" iyy="0.000001" iyz="0.0" izz="0.000001"/>
    </inertial>
  </link>
  <joint name="root_joint" type="fixed">
    <parent link="root"/>
    <child link="center_link"/>
    <origin rpy="0 0 0" xyz="0 0 0"/>
    <axis xyz="0 0 1"/>
  </joint>
    #### link ####
  <link name="center_link">
    <inertial>
      <origin rpy="0 0 0" xyz="-0.000001 0.000000 0.031426"/>
      <mass value="0.970304"/>
      <inertia ixx="0.011445" ixy="-0.000000" ixz="-0.000000" iyy="0.011444" iyz="0.000000" izz="0.021712"/>
    </inertial>
    <visual>
      <origin rpy="0 0 0" xyz="0 0 0"/>
      <geometry>
        <mesh filename="center_link.stl"/>
      </geometry>
    </visual>
    <collision name="center_link">
      <origin rpy="0 0 0" xyz="0 0 0"/>
      <geometry>
        <mesh filename="center_link.stl"/>
      </geometry>
    </collision>
  </link>
  <gazebo reference="center_link">
    <dampingFactor>0.00</dampingFactor>
  </gazebo>
    #### joints ####
    #### link joint ####
  <joint name="joint1" type="revolute">
    <limit effort="6.6" lower="-1.57" upper="1.57" velocity="3.0"/>
    <parent link="center_link"/>
    <child link="link1"/>
    <origin rpy="0 0 0" xyz="0.1555 0.0 0.015"/>
    <axis xyz="0 0 1"/>
    <dynamics damping="0.8" friction="0.0"/>
  </joint>
  <joint name="joint3" type="revolute">
    <limit effort="6.6" lower="-1.57" upper="1.57" velocity="3.0"/>
    <parent link="center_link"/>
    <child link="link3"/>
    <origin rpy="0 0 2.0943951023931953" xyz="-0.07775 0.13467 0.015"/>
    <axis xyz="0 0 1"/>
    <dynamics damping="0.8" friction="0.0"/>
  </joint>
  <joint name="joint5" type="revolute">
    <limit effort="6.6" lower="-1.57" upper="1.57" velocity="3.0"/>
    <parent link="center_link"/>
    <child link="link5"/>
    <origin rpy="0 0 4.1887902047863905" xyz="-0.07775 -0.13467 0.015"/>
    <axis xyz="0 0 1"/>
    <dynamics damping="0.8" friction="0.0"/>
  </joint>
    #### hardware interface ####
  <gazebo reference="linkcenter_link">
    <mu1>0.1</mu1>
    <mu2>0.1</mu2>
  </gazebo>
    #### link ####
  <link name="link1">
    <inertial>
      <origin rpy="0 0 0" xyz="0.313051 0.000071 0.011024"/>
      <mass value="0.535052"/>
      <inertia ixx="0.000808" ixy="0.000030" ixz="0.005073" iyy="0.014148" iyz="0.000002" izz="0.013428"/>
    </inertial>
    <visual>
      <origin rpy="0 0 3.141592653589793" xyz="0.6 0 0"/>
      <geometry>
        <mesh filename="middle_link.stl"/>
      </geometry>
    </visual>
    <collision name="link1">
      <origin rpy="0 0 3.141592653589793" xyz="0.6 0 0"/>
      <geometry>
        <mesh filename="middle_link.stl"/>
      </geometry>
    </collision>
  </link>
    #### link1 ####
  <gazebo reference="link1">
    <dampingFactor>0.00</dampingFactor>
  </gazebo>
    #### gimbal link ####
  <link name="gimbal_link1">
    <inertial>
      <origin rpy="0 0 0" xyz="-0.010664 0.000000 0.049923"/>
      <mass value="0.237140"/>
      <inertia ixx="0.004029" ixy="-0.000000" ixz="-0.001310" iyy="0.003369" iyz="0.000000" izz="0.006515"/>
    </inertial>
    <visual>
      <origin rpy="0 0 0" xyz="0 0 0"/>
      <geometry>
        <mesh filename="propeller_link.stl"/>
      </geometry>
    </visual>
    <collision name="gimbal_link1">
      <origin rpy="0 0 0" xyz="0 0 0"/>
      <geometry>
        <mesh filename="propeller_link.stl"/>
      </geometry>
    </collision>
  </link>
  <gazebo reference="gimbal_link1">
    <dampingFactor>0.00</dampingFactor>
  </gazebo>
    #### rotor parent link (virtual) ####
  <link name="rotor_parent1">
    <inertial>
      <origin rpy="0 0 0" xyz="0 0 0"/>
      <mass value="0.00001"/>
      <inertia ixx="0.000001" ixy="0.0" ixz="0.0" iyy="0.000001" iyz="0.0" izz="0.000001"/>
    </inertial>
  </link>
    #### thrust link (virtual) ####
  <link name="thrust1">
    <inertial>
      <origin rpy="0 0 0" xyz="0 0 0"/>
      <mass value="0.02"/>
      <inertia ixx="1.5841999999999998e-06" ixy="0.0" ixz="0.0" iyy="1.5841999999999998e-06" iyz="0.0" izz="3.1683999999999996e-06"/>
    </inertial>
    <visual>
      <origin rpy="0 0 0" xyz="0 0 0"/>
      <geometry>
        <mesh filename="T-motor-CF-14inch-CCW.stl"/>
      </geometry>
    </visual>
    <collision name="thrust1">
      <origin rpy="0 0 0" xyz="0 0 0"/>
      <geometry>
        <mesh filename="T-motor-CF-14inch-CCW.stl"/>
      </geometry>
    </collision>
  </link>
  <gazebo reference="thrust1">
    <dampingFactor>0.00</dampingFactor>
  </gazebo>
    #### joints ####
    #### link joint ####
  <joint name="joint2" type="revolute">
    <limit effort="6.6" lower="-1.5707963267948966" upper="1.5707963267948966" velocity="3.0"/>
    <parent link="link1"/>
    <child link="link2"/>
    <origin rpy="0 0 0" xyz="0.6 0 0"/>
    <axis xyz="0 0 1"/>
    <dynamics damping="0.8" friction="0.0"/>
  </joint>
    #### gimbal joint ####
  <joint name="gimbal1" type="continuous">
    <limit effort="3.1" lower="-18.84955592153876" upper="18.84955592153876" velocity="20.0"/>
    <parent link="link1"/>
    <child link="gimbal_link1"/>
    <origin rpy="0 0 3.141592653589793" xyz="0.2984 0 0.04867"/>
    <axis xyz="0 0 1"/>
    <dynamics damping="0.8" friction="0.0"/>
  </joint>
    #### rotor parent link joint (virtual) ####
  <joint name="rotor_parent_link_joint1" type="fixed">
    <parent link="gimbal_link1"/>
    <child link="rotor_parent1"/>
    <origin rpy="0 0.34906585039 0" xyz="0 0 0.06041"/>
    <axis xyz="0 0 1"/>
  </joint>
    #### rotor joint (virtual) ####
  <joint name="rotor1" type="continuous">
    <limit effort="100.0" lower="1" upper="35.5" velocity="0.5"/>
    <parent link="rotor_parent1"/>
    <child link="thrust1"/>
    <origin rpy="0 0 0" xyz="0 0 0"/>
    <axis xyz="0 0 1"/>
  </joint>
    #### battery ####
  <joint name="link12bat1" type="fixed">
    <parent link="link1"/>
    <child link="bat1"/>
    <origin rpy="0 0 1.5707963267948966" xyz="0.2867 0.0 -0.048"/>
  </joint>
  <link name="bat1">
    <inertial>
      <origin rpy="0 0 0" xyz="0 0 0"/>
      <mass value="0.193"/>
      <inertia ixx="0.00001" ixy="0.0" ixz="0.0" iyy="0.00001" iyz="0.0" izz="0.00002"/>
    </inertial>
    <visual>
      <geometry>
        <mesh filename="battery.stl"/>
      </geometry>
    </visual>
    <collision name="bat1">
      <geometry>
        <mesh filename="battery.stl"/>
      </geometry>
    </collision>
  </link>
    #### hardware interface ####
  <gazebo reference="link1">
    <mu1>0.1</mu1>
    <mu2>0.1</mu2>
  </gazebo>
    #### link ####
  <link name="link2">
    <inertial>
      <origin rpy="0 0 0" xyz="0.272827 0.000033 -0.006011"/>
      <mass value="0.455151"/>
      <inertia ixx="0.001020" ixy="0.000009" ixz="-0.002418" iyy="0.009477" iyz="0.000000" izz="0.008530"/>
    </inertial>
    <visual>
      <origin rpy="0 0 3.141592653589793" xyz="0.6 0 0"/>
      <geometry>
        <mesh filename="end_link1.stl"/>
      </geometry>
    </visual>
    <collision name="link2">
      <origin rpy="0 0 3.141592653589793" xyz="0.6 0 0"/>
      <geometry>
        <mesh filename="end_link1.stl"/>
      </geometry>
    </collision>
  </link>
    #### link2 ####
  <gazebo reference="link2">
    <dampingFactor>0.00</dampingFactor>
  </gazebo>
    #### gimbal link ####
  <link name="gimbal_link2">
    <inertial>
      <origin rpy="0 0 0" xyz="-0.010664 0.000000 0.049923"/>
      <mass value="0.237140"/>
      <inertia ixx="0.004029" ixy="-0.000000" ixz="-0.001310" iyy="0.003369" iyz="0.000000" izz="0.006515"/>
    </inertial>
    <visual>
      <origin rpy="0 0 0" xyz="0 0 0"/>
      <geometry>
        <mesh filename="propeller_link.stl"/>
      </geometry>
    </visual>
    <collision name="gimbal_link2">
      <origin rpy="0 0 0" xyz="0 0 0"/>
      <geometry>
        <mesh filename="propeller_link.stl"/>
      </geometry>
    </collision>
  </link>
  <gazebo reference="gimbal_link2">
    <dampingFactor>0.00</dampingFactor>
  </gazebo>
    #### rotor parent link (virtual) ####
  <link name="rotor_parent2">
    <inertial>
      <origin rpy="0 0 0" xyz="0 0 0"/>
      <mass value="0.00001"/>
      <inertia ixx="0.000001" ixy="0.0" ixz="0.0" iyy="0.000001" iyz="0.0" izz="0.000001"/>
    </inertial>
  </link>
    #### thrust link (virtual) ####
  <link name="thrust2">
    <inertial>
      <origin rpy="0 0 0" xyz="0 0 0"/>
      <mass value="0.02"/>
      <inertia ixx="1.5841999999999998e-06" ixy="0.0" ixz="0.0" iyy="1.5841999999999998e-06" iyz="0.0" izz="3.1683999999999996e-06"/>
    </inertial>
    <visual>
      <origin rpy="0 0 0" xyz="0 0 0"/>
      <geometry>
        <mesh filename="T-motor-CF-14inch-CW.stl"/>
      </geometry>
    </visual>
    <collision name="thrust2">
      <origin rpy="0 0 0" xyz="0 0 0"/>
      <geometry>
        <mesh filename="T-motor-CF-14inch-CW.stl"/>
      </geometry>
    </collision>
  </link>
  <gazebo reference="thrust2">
    <dampingFactor>0.00</dampingFactor>
  </gazebo>
    #### joints ####
    #### link joint ####
    #### gimbal joint ####
  <joint name="gimbal2" type="continuous">
    <limit effort="3.1" lower="-18.84955592153876" upper="18.84955592153876" velocity="20.0"/>
    <parent link="link2"/>
    <child link="gimbal_link2"/>
    <origin rpy="0 0 3.141592653589793" xyz="0.2984 0 0.04867"/>
    <axis xyz="0 0 1"/>
    <dynamics damping="0.8" friction="0.0"/>
  </joint>
    #### rotor parent link joint (virtual) ####
  <joint name="rotor_parent_link_joint2" type="fixed">
    <parent link="gimbal_link2"/>
    <child link="rotor_parent2"/>
    <origin rpy="0 0.34906585039 0" xyz="0 0 0.06041"/>
    <axis xyz="0 0 -1"/>
  </joint>
    #### rotor joint (virtual) ####
  <joint name="rotor2" type="continuous">
    <limit effort="100.0" lower="1" upper="35.5" velocity="0.5"/>
    <parent link="rotor_parent2"/>
    <child link="thrust2"/>
    <origin rpy="0 0 0" xyz="0 0 0"/>
    <axis xyz="0 0 -1"/>
  </joint>
    #### battery ####
  <joint name="link22bat2" type="fixed">
    <parent link="link2"/>
    <child link="bat2"/>
    <origin rpy="0 0 1.5707963267948966" xyz="0.2867 0.0 -0.048"/>
  </joint>
  <link name="bat2">
    <inertial>
      <origin rpy="0 0 0" xyz="0 0 0"/>
      <mass value="0.193"/>
      <inertia ixx="0.00001" ixy="0.0" ixz="0.0" iyy="0.00001" iyz="0.0" izz="0.00002"/>
    </inertial>
    <visual>
      <geometry>
        <mesh filename="battery.stl"/>
      </geometry>
    </visual>
    <collision name="bat2">
      <geometry>
        <mesh filename="battery.stl"/>
      </geometry>
    </collision>
  </link>
    #### hardware interface ####
  <gazebo reference="link2">
    <mu1>0.1</mu1>
    <mu2>0.1</mu2>
  </gazebo>
    #### link ####
  <link name="link3">
    <inertial>
      <origin rpy="0 0 0" xyz="0.313051 0.000071 0.011024"/>
      <mass value="0.535052"/>
      <inertia ixx="0.000808" ixy="0.000030" ixz="0.005073" iyy="0.014148" iyz="0.000002" izz="0.013428"/>
    </inertial>
    <visual>
      <origin rpy="0 0 3.141592653589793" xyz="0.6 0 0"/>
      <geometry>
        <mesh filename="middle_link.stl"/>
      </geometry>
    </visual>
    <collision name="link3">
      <origin rpy="0 0 3.141592653589793" xyz="0.6 0 0"/>
      <geometry>
        <mesh filename="middle_link.stl"/>
      </geometry>
    </collision>
  </link>
    #### link3 ####
  <gazebo reference="link3">
    <dampingFactor>0.00</dampingFactor>
  </gazebo>
    #### gimbal link ####
  <link name="gimbal_link3">
    <inertial>
      <origin rpy="0 0 0" xyz="-0.010664 0.000000 0.049923"/>
      <mass value="0.237140"/>
      <inertia ixx="0.004029" ixy="-0.000000" ixz="-0.001310" iyy="0.003369" iyz="0.000000" izz="0.006515"/>
    </inertial>
    <visual>
      <origin rpy="0 0 0" xyz="0 0 0"/>
      <geometry>
        <mesh filename="propeller_link.stl"/>
      </geometry>
    </visual>
    <collision name="gimbal_link3">
      <origin rpy="0 0 0" xyz="0 0 0"/>
      <geometry>
        <mesh filename="propeller_link.stl"/>
      </geometry>
    </collision>
  </link>
  <gazebo reference="gimbal_link3">
    <dampingFactor>0.00</dampingFactor>
  </gazebo>
    #### rotor parent link (virtual) ####
  <link name="rotor_parent3">
    <inertial>
      <origin rpy="0 0 0" xyz="0 0 0"/>
      <mass value="0.00001"/>
      <inertia ixx="0.000001" ixy="0.0" ixz="0.0" iyy="0.000001" iyz="0.0" izz="0.000001"/>
    </inertial>
  </link>
    #### thrust link (virtual) ####
  <link name="thrust3">
    <inertial>
      <origin rpy="0 0 0" xyz="0 0 0"/>
      <mass value="0.02"/>
      <inertia ixx="1.5841999999999998e-06" ixy="0.0" ixz="0.0" iyy="1.5841999999999998e-06" iyz="0.0" izz="3.1683999999999996e-06"/>
    </inertial>
    <visual>
      <origin rpy="0 0 0" xyz="0 0 0"/>
      <geometry>
        <mesh filename="T-motor-CF-14inch-CCW.stl"/>
      </geometry>
    </visual>
    <collision name="thrust3">
      <origin rpy="0 0 0" xyz="0 0 0"/>
      <geometry>
        <mesh filename="T-motor-CF-14inch-CCW.stl"/>
      </geometry>
    </collision>
  </link>
  <gazebo reference="thrust3">
    <dampingFactor>0.00</dampingFactor>
  </gazebo>
    #### joints ####
    #### link joint ####
  <joint name="joint4" type="revolute">
    <limit effort="6.6" lower="-1.5707963267948966" upper="1.5707963267948966" velocity="3.0"/>
    <parent link="link3"/>
    <child link="link4"/>
    <origin rpy="0 0 0" xyz="0.6 0 0"/>
    <axis xyz="0 0 1"/>
    <dynamics damping="0.8" friction="0.0"/>
  </joint>
    #### gimbal joint ####
  <joint name="gimbal3" type="continuous">
    <limit effort="3.1" lower="-18.84955592153876" upper="18.84955592153876" velocity="20.0"/>
    <parent link="link3"/>
    <child link="gimbal_link3"/>
    <origin rpy="0 0 3.141592653589793" xyz="0.2984 0 0.04867"/>
    <axis xyz="0 0 1"/>
    <dynamics damping="0.8" friction="0.0"/>
  </joint>
    #### rotor parent link joint (virtual) ####
  <joint name="rotor_parent_link_joint3" type="fixed">
    <parent link="gimbal_link3"/>
    <child link="rotor_parent3"/>
    <origin rpy="0 0.34906585039 0" xyz="0 0 0.06041"/>
    <axis xyz="0 0 1"/>
  </joint>
    #### rotor joint (virtual) ####
  <joint name="rotor3" type="continuous">
    <limit effort="100.0" lower="1" upper="35.5" velocity="0.5"/>
    <parent link="rotor_parent3"/>
    <child link="thrust3"/>
    <origin rpy="0 0 0" xyz="0 0 0"/>
    <axis xyz="0 0 1"/>
  </joint>
    #### battery ####
  <joint name="link32bat3" type="fixed">
    <parent link="link3"/>
    <child link="bat3"/>
    <origin rpy="0 0 1.5707963267948966" xyz="0.2867 0.0 -0.048"/>
  </joint>
  <link name="bat3">
    <inertial>
      <origin rpy="0 0 0" xyz="0 0 0"/>
      <mass value="0.193"/>
      <inertia ixx="0.00001" ixy="0.0" ixz="0.0" iyy="0.00001" iyz="0.0" izz="0.00002"/>
    </inertial>
    <visual>
      <geometry>
        <mesh filename="battery.stl"/>
      </geometry>
    </visual>
    <collision name="bat3">
      <geometry>
        <mesh filename="battery.stl"/>
      </geometry>
    </collision>
  </link>
    #### hardware interface ####
  <gazebo reference="link3">
    <mu1>0.1</mu1>
    <mu2>0.1</mu2>
  </gazebo>
    #### link ####
  <link name="link4">
    <inertial>
      <origin rpy="0 0 0" xyz="0.272827 0.000033 -0.006011"/>
      <mass value="0.455151"/>
      <inertia ixx="0.001020" ixy="0.000009" ixz="-0.002418" iyy="0.009477" iyz="0.000000" izz="0.008530"/>
    </inertial>
    <visual>
      <origin rpy="0 0 3.141592653589793" xyz="0.6 0 0"/>
      <geometry>
        <mesh filename="end_link1.stl"/>
      </geometry>
    </visual>
    <collision name="link4">
      <origin rpy="0 0 3.141592653589793" xyz="0.6 0 0"/>
      <geometry>
        <mesh filename="end_link1.stl"/>
      </geometry>
    </collision>
  </link>
    #### link4 ####
  <gazebo reference="link4">
    <dampingFactor>0.00</dampingFactor>
  </gazebo>
    #### gimbal link ####
  <link name="gimbal_link4">
    <inertial>
      <origin rpy="0 0 0" xyz="-0.010664 0.000000 0.049923"/>
      <mass value="0.237140"/>
      <inertia ixx="0.004029" ixy="-0.000000" ixz="-0.001310" iyy="0.003369" iyz="0.000000" izz="0.006515"/>
    </inertial>
    <visual>
      <origin rpy="0 0 0" xyz="0 0 0"/>
      <geometry>
        <mesh filename="propeller_link.stl"/>
      </geometry>
    </visual>
    <collision name="gimbal_link4">
      <origin rpy="0 0 0" xyz="0 0 0"/>
      <geometry>
        <mesh filename="propeller_link.stl"/>
      </geometry>
    </collision>
  </link>
  <gazebo reference="gimbal_link4">
    <dampingFactor>0.00</dampingFactor>
  </gazebo>
    #### rotor parent link (virtual) ####
  <link name="rotor_parent4">
    <inertial>
      <origin rpy="0 0 0" xyz="0 0 0"/>
      <mass value="0.00001"/>
      <inertia ixx="0.000001" ixy="0.0" ixz="0.0" iyy="0.000001" iyz="0.0" izz="0.000001"/>
    </inertial>
  </link>
    #### thrust link (virtual) ####
  <link name="thrust4">
    <inertial>
      <origin rpy="0 0 0" xyz="0 0 0"/>
      <mass value="0.02"/>
      <inertia ixx="1.5841999999999998e-06" ixy="0.0" ixz="0.0" iyy="1.5841999999999998e-06" iyz="0.0" izz="3.1683999999999996e-06"/>
    </inertial>
    <visual>
      <origin rpy="0 0 0" xyz="0 0 0"/>
      <geometry>
        <mesh filename="T-motor-CF-14inch-CW.stl"/>
      </geometry>
    </visual>
    <collision name="thrust4">
      <origin rpy="0 0 0" xyz="0 0 0"/>
      <geometry>
        <mesh filename="T-motor-CF-14inch-CW.stl"/>
      </geometry>
    </collision>
  </link>
  <gazebo reference="thrust4">
    <dampingFactor>0.00</dampingFactor>
  </gazebo>
    #### joints ####
    #### link joint ####
    #### gimbal joint ####
  <joint name="gimbal4" type="continuous">
    <limit effort="3.1" lower="-18.84955592153876" upper="18.84955592153876" velocity="20.0"/>
    <parent link="link4"/>
    <child link="gimbal_link4"/>
    <origin rpy="0 0 3.141592653589793" xyz="0.2984 0 0.04867"/>
    <axis xyz="0 0 1"/>
    <dynamics damping="0.8" friction="0.0"/>
  </joint>
    #### rotor parent link joint (virtual) ####
  <joint name="rotor_parent_link_joint4" type="fixed">
    <parent link="gimbal_link4"/>
    <child link="rotor_parent4"/>
    <origin rpy="0 0.34906585039 0" xyz="0 0 0.06041"/>
    <axis xyz="0 0 -1"/>
  </joint>
    #### rotor joint (virtual) ####
  <joint name="rotor4" type="continuous">
    <limit effort="100.0" lower="1" upper="35.5" velocity="0.5"/>
    <parent link="rotor_parent4"/>
    <child link="thrust4"/>
    <origin rpy="0 0 0" xyz="0 0 0"/>
    <axis xyz="0 0 -1"/>
  </joint>
    #### battery ####
  <joint name="link42bat4" type="fixed">
    <parent link="link4"/>
    <child link="bat4"/>
    <origin rpy="0 0 1.5707963267948966" xyz="0.2867 0.0 -0.048"/>
  </joint>
  <link name="bat4">
    <inertial>
      <origin rpy="0 0 0" xyz="0 0 0"/>
      <mass value="0.193"/>
      <inertia ixx="0.00001" ixy="0.0" ixz="0.0" iyy="0.00001" iyz="0.0" izz="0.00002"/>
    </inertial>
    <visual>
      <geometry>
        <mesh filename="battery.stl"/>
      </geometry>
    </visual>
    <collision name="bat4">
      <geometry>
        <mesh filename="battery.stl"/>
      </geometry>
    </collision>
  </link>
    #### hardware interface ####
  <gazebo reference="link4">
    <mu1>0.1</mu1>
    <mu2>0.1</mu2>
  </gazebo>
    #### link ####
  <link name="link5">
    <inertial>
      <origin rpy="0 0 0" xyz="0.313051 0.000071 0.011024"/>
      <mass value="0.535052"/>
      <inertia ixx="0.000808" ixy="0.000030" ixz="0.005073" iyy="0.014148" iyz="0.000002" izz="0.013428"/>
    </inertial>
    <visual>
      <origin rpy="0 0 3.141592653589793" xyz="0.6 0 0"/>
      <geometry>
        <mesh filename="middle_link.stl"/>
      </geometry>
    </visual>
    <collision name="link5">
      <origin rpy="0 0 3.141592653589793" xyz="0.6 0 0"/>
      <geometry>
        <mesh filename="middle_link.stl"/>
      </geometry>
    </collision>
  </link>
    #### link5 ####
  <gazebo reference="link5">
    <dampingFactor>0.00</dampingFactor>
  </gazebo>
    #### gimbal link ####
  <link name="gimbal_link5">
    <inertial>
      <origin rpy="0 0 0" xyz="-0.010664 0.000000 0.049923"/>
      <mass value="0.237140"/>
      <inertia ixx="0.004029" ixy="-0.000000" ixz="-0.001310" iyy="0.003369" iyz="0.000000" izz="0.006515"/>
    </inertial>
    <visual>
      <origin rpy="0 0 0" xyz="0 0 0"/>
      <geometry>
        <mesh filename="propeller_link.stl"/>
      </geometry>
    </visual>
    <collision name="gimbal_link5">
      <origin rpy="0 0 0" xyz="0 0 0"/>
      <geometry>
        <mesh filename="propeller_link.stl"/>
      </geometry>
    </collision>
  </link>
  <gazebo reference="gimbal_link5">
    <dampingFactor>0.00</dampingFactor>
  </gazebo>
    #### rotor parent link (virtual) ####
  <link name="rotor_parent5">
    <inertial>
      <origin rpy="0 0 0" xyz="0 0 0"/>
      <mass value="0.00001"/>
      <inertia ixx="0.000001" ixy="0.0" ixz="0.0" iyy="0.000001" iyz="0.0" izz="0.000001"/>
    </inertial>
  </link>
    #### thrust link (virtual) ####
  <link name="thrust5">
    <inertial>
      <origin rpy="0 0 0" xyz="0 0 0"/>
      <mass value="0.02"/>
      <inertia ixx="1.5841999999999998e-06" ixy="0.0" ixz="0.0" iyy="1.5841999999999998e-06" iyz="0.0" izz="3.1683999999999996e-06"/>
    </inertial>
    <visual>
      <origin rpy="0 0 0" xyz="0 0 0"/>
      <geometry>
        <mesh filename="T-motor-CF-14inch-CCW.stl"/>
      </geometry>
    </visual>
    <collision name="thrust5">
      <origin rpy="0 0 0" xyz="0 0 0"/>
      <geometry>
        <mesh filename="T-motor-CF-14inch-CCW.stl"/>
      </geometry>
    </collision>
  </link>
  <gazebo reference="thrust5">
    <dampingFactor>0.00</dampingFactor>
  </gazebo>
    #### joints ####
    #### link joint ####
  <joint name="joint6" type="revolute">
    <limit effort="6.6" lower="-1.5707963267948966" upper="1.5707963267948966" velocity="3.0"/>
    <parent link="link5"/>
    <child link="link6"/>
    <origin rpy="0 0 0" xyz="0.6 0 0"/>
    <axis xyz="0 0 1"/>
    <dynamics damping="0.8" friction="0.0"/>
  </joint>
    #### gimbal joint ####
  <joint name="gimbal5" type="continuous">
    <limit effort="3.1" lower="-18.84955592153876" upper="18.84955592153876" velocity="20.0"/>
    <parent link="link5"/>
    <child link="gimbal_link5"/>
    <origin rpy="0 0 3.141592653589793" xyz="0.2984 0 0.04867"/>
    <axis xyz="0 0 1"/>
    <dynamics damping="0.8" friction="0.0"/>
  </joint>
    #### rotor parent link joint (virtual) ####
  <joint name="rotor_parent_link_joint5" type="fixed">
    <parent link="gimbal_link5"/>
    <child link="rotor_parent5"/>
    <origin rpy="0 0.34906585039 0" xyz="0 0 0.06041"/>
    <axis xyz="0 0 1"/>
  </joint>
    #### rotor joint (virtual) ####
  <joint name="rotor5" type="continuous">
    <limit effort="100.0" lower="1" upper="35.5" velocity="0.5"/>
    <parent link="rotor_parent5"/>
    <child link="thrust5"/>
    <origin rpy="0 0 0" xyz="0 0 0"/>
    <axis xyz="0 0 1"/>
  </joint>
    #### battery ####
  <joint name="link52bat5" type="fixed">
    <parent link="link5"/>
    <child link="bat5"/>
    <origin rpy="0 0 1.5707963267948966" xyz="0.2867 0.0 -0.048"/>
  </joint>
  <link name="bat5">
    <inertial>
      <origin rpy="0 0 0" xyz="0 0 0"/>
      <mass value="0.193"/>
      <inertia ixx="0.00001" ixy="0.0" ixz="0.0" iyy="0.00001" iyz="0.0" izz="0.00002"/>
    </inertial>
    <visual>
      <geometry>
        <mesh filename="battery.stl"/>
      </geometry>
    </visual>
    <collision name="bat5">
      <geometry>
        <mesh filename="battery.stl"/>
      </geometry>
    </collision>
  </link>
    #### hardware interface ####
  <gazebo reference="link5">
    <mu1>0.1</mu1>
    <mu2>0.1</mu2>
  </gazebo>
    #### link ####
  <link name="link6">
    <inertial>
      <origin rpy="0 0 0" xyz="0.272827 0.000033 -0.006011"/>
      <mass value="0.455151"/>
      <inertia ixx="0.001020" ixy="0.000009" ixz="-0.002418" iyy="0.009477" iyz="0.000000" izz="0.008530"/>
    </inertial>
    <visual>
      <origin rpy="0 0 3.141592653589793" xyz="0.6 0 0"/>
      <geometry>
        <mesh filename="end_link1.stl"/>
      </geometry>
    </visual>
    <collision name="link6">
      <origin rpy="0 0 3.141592653589793" xyz="0.6 0 0"/>
      <geometry>
        <mesh filename="end_link1.stl"/>
      </geometry>
    </collision>
  </link>
    #### link6 ####
  <gazebo reference="link6">
    <dampingFactor>0.00</dampingFactor>
  </gazebo>
    #### gimbal link ####
  <link name="gimbal_link6">
    <inertial>
      <origin rpy="0 0 0" xyz="-0.010664 0.000000 0.049923"/>
      <mass value="0.237140"/>
      <inertia ixx="0.004029" ixy="-0.000000" ixz="-0.001310" iyy="0.003369" iyz="0.000000" izz="0.006515"/>
    </inertial>
    <visual>
      <origin rpy="0 0 0" xyz="0 0 0"/>
      <geometry>
        <mesh filename="propeller_link.stl"/>
      </geometry>
    </visual>
    <collision name="gimbal_link6">
      <origin rpy="0 0 0" xyz="0 0 0"/>
      <geometry>
        <mesh filename="propeller_link.stl"/>
      </geometry>
    </collision>
  </link>
  <gazebo reference="gimbal_link6">
    <dampingFactor>0.00</dampingFactor>
  </gazebo>
    #### rotor parent link (virtual) ####
  <link name="rotor_parent6">
    <inertial>
      <origin rpy="0 0 0" xyz="0 0 0"/>
      <mass value="0.00001"/>
      <inertia ixx="0.000001" ixy="0.0" ixz="0.0" iyy="0.000001" iyz="0.0" izz="0.000001"/>
    </inertial>
  </link>
    #### thrust link (virtual) ####
  <link name="thrust6">
    <inertial>
      <origin rpy="0 0 0" xyz="0 0 0"/>
      <mass value="0.02"/>
      <inertia ixx="1.5841999999999998e-06" ixy="0.0" ixz="0.0" iyy="1.5841999999999998e-06" iyz="0.0" izz="3.1683999999999996e-06"/>
    </inertial>
    <visual>
      <origin rpy="0 0 0" xyz="0 0 0"/>
      <geometry>
        <mesh filename="T-motor-CF-14inch-CW.stl"/>
      </geometry>
    </visual>
    <collision name="thrust6">
      <origin rpy="0 0 0" xyz="0 0 0"/>
      <geometry>
        <mesh filename="T-motor-CF-14inch-CW.stl"/>
      </geometry>
    </collision>
  </link>
  <gazebo reference="thrust6">
    <dampingFactor>0.00</dampingFactor>
  </gazebo>
    #### joints ####
    #### link joint ####
    #### gimbal joint ####
  <joint name="gimbal6" type="continuous">
    <limit effort="3.1" lower="-18.84955592153876" upper="18.84955592153876" velocity="20.0"/>
    <parent link="link6"/>
    <child link="gimbal_link6"/>
    <origin rpy="0 0 3.141592653589793" xyz="0.2984 0 0.04867"/>
    <axis xyz="0 0 1"/>
    <dynamics damping="0.8" friction="0.0"/>
  </joint>
    #### rotor parent link joint (virtual) ####
  <joint name="rotor_parent_link_joint6" type="fixed">
    <parent link="gimbal_link6"/>
    <child link="rotor_parent6"/>
    <origin rpy="0 0.34906585039 0" xyz="0 0 0.06041"/>
    <axis xyz="0 0 -1"/>
  </joint>
    #### rotor joint (virtual) ####
  <joint name="rotor6" type="continuous">
    <limit effort="100.0" lower="1" upper="35.5" velocity="0.5"/>
    <parent link="rotor_parent6"/>
    <child link="thrust6"/>
    <origin rpy="0 0 0" xyz="0 0 0"/>
    <axis xyz="0 0 -1"/>
  </joint>
    #### battery ####
  <joint name="link62bat6" type="fixed">
    <parent link="link6"/>
    <child link="bat6"/>
    <origin rpy="0 0 1.5707963267948966" xyz="0.2867 0.0 -0.048"/>
  </joint>
  <link name="bat6">
    <inertial>
      <origin rpy="0 0 0" xyz="0 0 0"/>
      <mass value="0.193"/>
      <inertia ixx="0.00001" ixy="0.0" ixz="0.0" iyy="0.00001" iyz="0.0" izz="0.00002"/>
    </inertial>
    <visual>
      <geometry>
        <mesh filename="battery.stl"/>
      </geometry>
    </visual>
    <collision name="bat6">
      <geometry>
        <mesh filename="battery.stl"/>
      </geometry>
    </collision>
  </link>
    #### hardware interface ####
  <gazebo reference="link6">
    <mu1>0.1</mu1>
    <mu2>0.1</mu2>
  </gazebo>
  #### flight controller ####
  <joint name="center_link2fc" type="fixed">
    <parent link="center_link"/>
    <child link="fc"/>
    <origin rpy="0 0 0" xyz="-0.0129 -0.0044 0.03933"/>
  </joint>
  <link name="fc">
    <inertial>
      <origin rpy="0 0 0" xyz="0.012999 0.004396 -0.004856"/>
      <mass value="0.009434"/>
      <inertia ixx="0.000004" ixy="0.000001" ixz="-0.000001" iyy="0.000004" iyz="-0.000000" izz="0.000008"/>
    </inertial>
    <visual>
      <geometry>
        <mesh filename="fc3.stl"/>
      </geometry>
    </visual>
    <collision name="fc">
      <geometry>
        <mesh filename="fc3.stl"/>
      </geometry>
    </collision>
  </link>
  <joint name="center_link2pc" type="fixed">
    <parent link="center_link"/>
    <child link="pc"/>
    <origin rpy="0 0 0" xyz="-0.01075 0.0005 -0.0775"/>
  </joint>
  <link name="pc">
    <inertial>
      <origin rpy="0 0 0" xyz="-0.000890 -0.000110 0.028700"/>
      <mass value="0.449000"/>
      <inertia ixx="-0.000452" ixy="0.000000" ixz="-0.000014" iyy="-0.000453" iyz="-0.000002" izz="-0.000000"/>
    </inertial>
    <visual>
      <geometry>
        <mesh filename="xavier_2.stl"/>
      </geometry>
    </visual>
    <collision name="pc">
      <geometry>
        <mesh filename="xavier_2.stl"/>
      </geometry>
    </collision>
  </link>
  <joint name="center_link2zed_camera_center" type="fixed">
    <parent link="center_link"/>
    <child link="zed_camera_center"/>
    <origin rpy="0 0 1.0471975511965976" xyz="0.05504 0.09534  0.029"/>
  </joint>
  <link name="zed_camera_center">
    <inertial>
      <origin rpy="0 0 0" xyz="0.000430 0.006110 0.000000"/>
      <mass value="0.090000"/>
      <inertia ixx="0.000117" ixy="0.000000" ixz="0.000000" iyy="0.000010" iyz="0.000000" izz="0.000117"/>
    </inertial>
    <visual>
      <geometry>
        <mesh filename="zed_mini.stl"/>
      </geometry>
    </visual>
    <collision name="zed_camera_center">
      <geometry>
        <mesh filename="zed_mini.stl"/>
      </geometry>
    </collision>
  </link>
  <joint name="center_link2leddarone" type="fixed">
    <parent link="center_link"/>
    <child link="leddarone"/>
    <origin rpy="0 3.141592653589793 -1.5707963267948966" xyz="0.082 0.0 -0.027"/>
  </joint>
  <link name="leddarone">
    <inertial>
      <origin rpy="0 0 0" xyz="0.000000 -0.009700 -0.004610"/>
      <mass value="0.028000"/>
      <inertia ixx="0.000007" ixy="0.000000" ixz="0.000000" iyy="0.000009" iyz="0.000001" izz="0.000007"/>
    </inertial>
    <visual>
      <geometry>
        <mesh filename="leddar_one.stl"/>
      </geometry>
    </visual>
    <collision name="leddarone">
      <geometry>
        <mesh filename="leddar_one.stl"/>
      </geometry>
    </collision>
  </link>
  <joint name="laser_joint" type="fixed">
    <origin rpy="0 0 3.141592653589793" xyz="0.0 0.0 0.2774"/>
    <parent link="center_link"/>
    <child link="laser_frame"/>
  </joint>
  <link name="laser_frame">
    <inertial>
      <origin rpy="0 0 0" xyz="-0.000570 0.000005 -0.064301"/>
      <mass value="0.2568"/>
      <inertia ixx="0.002067" ixy="-0.000000" ixz="0.000005" iyy="0.002077" iyz="-0.000000" izz="0.000470"/>
    </inertial>
    <visual>
      <origin rpy="0 0 0" xyz="0 0 0"/>
      <geometry>
        <mesh filename="ust20lx_with_mount.stl"/>
      </geometry>
    </visual>
    <collision name="laser_frame">
      <origin rpy="0 0 0" xyz="0 0 0"/>
      <geometry>
        <mesh filename="ust20lx_with_mount.stl"/>
      </geometry>
    </collision>
  </link>
  <gazebo reference="laser_frame">
    <sensor name="laser" type="ray">
      <always_on>true</always_on>
      <update_rate>40</update_rate>
      <pose>0 0 0 0 0 0</pose>
      <visualize>false</visualize>
      <ray>
        <scan>
          <horizontal>
            <samples>1081</samples>
            <resolution>1</resolution>
            <min_angle>-2.356194490192345</min_angle>
            <max_angle>2.356194490192345</max_angle>
          </horizontal>
        </scan>
        <range>
          <min>0.1</min>
          <max>20.0</max>
          <resolution>0.01</resolution>
        </range>
        <noise>
          <type>gaussian</type>
          <mean>0.0</mean>
          <stddev>0.004</stddev>
        </noise>
      </ray>
      <plugin filename="libgazebo_ros_laser.so" name="gazebo_ros_laser_controller">
        <topicName>scan</topicName>
        <frameName>laser_frame</frameName>
      </plugin>
    </sensor>
  </gazebo>
  <joint name="center_link2gps" type="fixed">
    <parent link="center_link"/>
    <child link="gps"/>
    <origin rpy="0 0 0" xyz="0.0 0.0 0.3"/>
  </joint>
  <link name="gps">
    <inertial>
      <origin rpy="0 0 0" xyz="0.0 0.0 0.0"/>
      <mass value="0.03"/>
      <inertia ixx="0.0" ixy="0.0" ixz="0.0" iyy="0.0" iyz="0.0" izz="0.0"/>
    </inertial>
    <visual>
      <geometry>
        <mesh filename="gps_m8nblox.stl"/>
      </geometry>
    </visual>
    <collision name="gps">
      <geometry>
        <mesh filename="gps_m8nblox.stl"/>
      </geometry>
    </collision>
  </link>
  <mujoco>
    <compiler balanceinertia="true"/>
    <option/>
  </mujoco>
</robot>
