<?xml version="1.0" ?>
<mujoco model="hydrus">
  <compiler angle="radian" autolimits="true" balanceinertia="true"/>
  <statistic meansize="0.307642" extent="2.53332" center="1.20014 1.77359e-05 0.0233221"/>
  <asset>
    <mesh name="link1" file="link1.stl"/>
    <mesh name="T-motor-CF-14inch-CW" file="T-motor-CF-14inch-CW.stl"/>
    <mesh name="end_leg" file="end_leg.stl"/>
    <mesh name="link2" file="link2.stl"/>
    <mesh name="T-motor-CF-14inch-CCW" file="T-motor-CF-14inch-CCW.stl"/>
    <mesh name="joint_leg" file="joint_leg.stl"/>
    <mesh name="link3" file="link3.stl"/>
    <mesh name="link4" file="link4.stl"/>
    <mesh name="Kypom-3000-6s" file="Kypom-3000-6s.stl"/>
    <mesh name="spinal" file="spinal.stl"/>
    <mesh name="jetson_tx2_unit" file="jetson_tx2_unit.stl"/>
    <mesh name="leddar_one_tx2_attached_mode" file="leddar_one_tx2_attached_mode.stl"/>
    <mesh name="gps_ublox_m8n" file="gps_ublox_m8n.stl"/>
  </asset>
  <worldbody>
    <body name="link1" pos="0 0 0.2">
      <inertial pos="0.357 0.0 0.018" mass="0.58712" fullinertia="0.00179 0.01605 0.01714 0.00000 0.00067 0.00000"/>
      <freejoint/>
      <geom name="link1" pos="0.3 0 0" type="mesh" mesh="link1" contype="1" conaffinity="0"/>
      <geom name="leg1" pos="0.04116 0 0" type="mesh" mesh="end_leg" contype="1" conaffinity="0"/>
      <geom name="bat1" pos="0.3 0 -0.048" type="mesh" mesh="Kypom-3000-6s" contype="1" conaffinity="0"/>
      <body name="thrust1" pos="0.3 0 0.013">
        <inertial pos="0 0 0" quat="0.5 0.5 -0.5 0.5" mass="0.0001" diaginertia="2e-05 1e-05 1e-05"/>
        <geom name="thrust1" pos="0 0 0.032" type="mesh" mesh="T-motor-CF-14inch-CW" contype="1" conaffinity="0"/>
        <site name="rotor1" pos="0 0 0"/>
      </body>
      <body name="link2" pos="0.6 0 0">
        <inertial pos="0.3082 3.38095e-05 0.0131317" quat="0.517069 0.480731 0.465303 0.533883" mass="0.69655" diaginertia="0.0273141 0.027259 0.002984"/>
        <joint name="joint1" pos="0 0 0" axis="0 0 1" range="-1.5708 1.5708" damping="150" frictionloss="0.05"/>
        <geom name="link2" pos="0.3 0 0" type="mesh" mesh="link2" contype="1" conaffinity="0"/>
        <geom name="leg2" type="mesh" mesh="joint_leg" contype="1" conaffinity="0"/>
        <geom name="fc" pos="0.5221 -0.0044 0.02135" type="mesh" mesh="spinal" contype="1" conaffinity="0"/>
        <geom name="gps" pos="0.4925 0 0.152" type="mesh" mesh="gps_ublox_m8n" contype="1" conaffinity="0"/>
        <body name="thrust2" pos="0.3 0 0.013">
          <inertial pos="0 0 0" quat="0.5 0.5 -0.5 0.5" mass="0.0001" diaginertia="2e-05 1e-05 1e-05"/>
          <geom name="thrust2" pos="0 0 0.032" type="mesh" mesh="T-motor-CF-14inch-CCW" contype="1" conaffinity="0"/>
          <site name="rotor2" pos="0 0 0"/>
        </body>
        <body name="link3" pos="0.6 0 0">
          <inertial pos="0.21116 0.000842186 0.000600002" quat="0.522379 0.476926 0.463313 0.533856" mass="0.88763" diaginertia="0.0310266 0.0305747 0.00265922"/>
          <joint name="joint2" pos="0 0 0" axis="0 0 1" range="-1.5708 1.5708" damping="150" frictionloss="0.05"/>
          <geom name="link3" pos="0.3 0 0" type="mesh" mesh="link3" contype="1" conaffinity="0"/>
          <geom name="leg3" type="mesh" mesh="joint_leg" contype="1" conaffinity="0"/>
          <geom name="pc" pos="0.06225 0 -0.01" type="mesh" mesh="jetson_tx2_unit" contype="1" conaffinity="0"/>
          <geom name="leddarone" pos="0.1145 0 -0.0626" quat="0 1 0 0" type="mesh" mesh="leddar_one_tx2_attached_mode" contype="1" conaffinity="0"/>
          <body name="thrust3" pos="0.3 0 0.013">
            <inertial pos="0 0 0" quat="0.5 0.5 -0.5 0.5" mass="0.0001" diaginertia="2e-05 1e-05 1e-05"/>
            <geom name="thrust3" pos="0 0 0.032" type="mesh" mesh="T-motor-CF-14inch-CW" contype="1" conaffinity="0"/>
            <site name="rotor3" pos="0 0 0"/>
          </body>
          <body name="link4" pos="0.6 0 0">
            <inertial pos="0.266978 4.30137e-05 -0.0160213" quat="0.495015 0.50495 0.503215 0.49675" mass="1.095" diaginertia="0.0267974 0.0257332 0.00410426"/>
            <joint name="joint3" pos="0 0 0" axis="0 0 1" range="-1.5708 1.5708" damping="150" frictionloss="0.05"/>
            <geom name="link4" pos="0.3 0 0" type="mesh" mesh="link4" contype="1" conaffinity="0"/>
            <geom name="leg4" type="mesh" mesh="joint_leg" contype="1" conaffinity="0"/>
            <geom name="leg5" pos="0.55884 0 0" type="mesh" mesh="end_leg" contype="1" conaffinity="0"/>
            <geom name="bat2" pos="0.3 0 -0.048" type="mesh" mesh="Kypom-3000-6s" contype="1" conaffinity="0"/>
            <body name="thrust4" pos="0.3 0 0.013">
              <inertial pos="0 0 0" quat="0.5 0.5 -0.5 0.5" mass="0.0001" diaginertia="2e-05 1e-05 1e-05"/>
              <geom name="thrust4" pos="0 0 0.032" type="mesh" mesh="T-motor-CF-14inch-CCW" contype="1" conaffinity="0"/>
              <site name="rotor4" pos="0 0 0"/>
            </body>
          </body>
        </body>
        <site name="fc" pos="0.5221 -0.0044 0.02135"/>
      </body>
      <body name="leg1" pos="0.04116 0 0" quat="1 0 0 0">
        <inertial pos="0.0 0.0005 -0.09411" mass="0.0471" fullinertia="0.000251 0.000242 0.000011 0.000000 0.000000 0.000000"/>
      </body>
      <body name="bat1" pos="0.3 0 -0.048" quat="1 0 0 0">
        <inertial pos="0 0 0" mass="0.4108" fullinertia="0.0001 0.0006 0.0006 0.0 0.0 0.0"/>
      </body>
    </body>
  </worldbody>
  <actuator>
    <motor name="rotor1" ctrllimited="true" ctrlrange="1 20" gear="0 0 1 0 0 0.0172" site="rotor1"/>
    <motor name="rotor2" ctrllimited="true" ctrlrange="1 20" gear="0 0 1 0 0 -0.0172" site="rotor2"/>
    <motor name="rotor3" ctrllimited="true" ctrlrange="1 20" gear="0 0 1 0 0 0.0172" site="rotor3"/>
    <motor name="rotor4" ctrllimited="true" ctrlrange="1 20" gear="0 0 1 0 0 -0.0172" site="rotor4"/>
    <position name="joint1" kp="40" joint="joint1"/>
    <position name="joint2" kp="40" joint="joint2"/>
    <position name="joint3" kp="40" joint="joint3"/>
  </actuator>
  <sensor>
    <accelerometer name="acc" site="fc"/>
    <gyro name="gyro" site="fc"/>
    <magnetometer name="mag" site="fc"/>
  </sensor>
  <include file="../../../../../../aerial_robot_3rdparty/mujoco_ros_control/config/world.xml"/>
</mujoco>
