<?xml version="1.0" ?>
<robot name="dragon">
  <baselink name="fc"/>
  <thrust_link name="thrust"/>
  <m_f_rate value="0"/>
  <link name="link1">
    <inertial>
      <origin rpy="0 0 0" xyz="0.22709 -0.00667 -0.02721"/>
      <mass value="0.7968"/>
      <inertia ixx="0.00095" ixy="-0.00098" ixz="0.0003" iyy="0.0151" iyz="0.0001" izz="0.0148"/>
    </inertial>
    <visual>
      <origin rpy="0 0 0" xyz="0.212 0 0"/>
      <geometry>
        <mesh filename="ducted_fan_head_link.stl"/>
      </geometry>
    </visual>
    <collision name="link1">
      <origin rpy="0 0 0" xyz="0.212 0 0"/>
      <geometry>
        <mesh filename="ducted_fan_head_link.stl"/>
      </geometry>
    </collision>
  </link>
  <gazebo reference="link1">
    <dampingFactor>0.00</dampingFactor>
  </gazebo>
  <joint name="gimbal1_roll" type="revolute">
    <limit effort="3" lower="-3.14" upper="3.14" velocity="12.5"/>
    <parent link="link1"/>
    <child link="gimbal1_roll_module"/>
    <origin rpy="0 0 0" xyz="0.212 0 0"/>
    <axis xyz="1 0 0"/>
    <dynamics damping="0.1" friction="0.0"/>
  </joint>
  <link name="gimbal1_roll_module">
    <inertial>
      <origin rpy="0 0 0" xyz="-0.0276 0.00042 0.01548"/>
      <mass value="0.4604"/>
      <inertia ixx="0.0004" ixy="0" ixz="-0.0003" iyy="0.0004" iyz="0" izz="0.0003"/>
    </inertial>
    <visual>
      <origin rpy="0 0 0" xyz="-0.01 0 0"/>
      <geometry>
        <mesh filename="ducted_fan_gimbal_roll.stl"/>
      </geometry>
    </visual>
    <collision name="gimbal1_roll_module">
      <origin rpy="0 0 0" xyz="-0.01 0 0"/>
      <geometry>
        <mesh filename="ducted_fan_gimbal_roll.stl"/>
      </geometry>
    </collision>
  </link>
  <joint name="gimbal1_pitch" type="revolute">
    <limit effort="3" lower="-3.14" upper="3.14" velocity="12.5"/>
    <parent link="gimbal1_roll_module"/>
    <child link="gimbal1_pitch_module"/>
    <origin rpy="0 0 0" xyz="0 0 0.037"/>
    <axis xyz="0 1 0"/>
    <dynamics damping="0.1" friction="0.0"/>
  </joint>
  <link name="gimbal1_pitch_module">
    <inertial>
      <origin rpy="0 0 0" xyz="0 0.00033  -0.00871"/>
      <mass value="0.5301"/>
      <inertia ixx="0.0061" ixy="0.0" ixz="0.0" iyy="0.0001" iyz="0.0" izz="0.0061"/>
    </inertial>
    <visual>
      <origin rpy="0 0 0" xyz="0 0 0"/>
      <geometry>
        <mesh filename="ducted_fan_gimbal_pitch.stl"/>
      </geometry>
    </visual>
    <collision name="gimbal1_pitch_module">
      <origin rpy="0 0 0" xyz="0 0 0"/>
      <geometry>
        <mesh filename="ducted_fan_gimbal_pitch.stl"/>
      </geometry>
    </collision>
  </link>
  <joint name="rotor1" type="continuous">
    <limit effort="100.0" lower="2" upper="30" velocity="0.5"/>
    <parent link="gimbal1_pitch_module"/>
    <child link="thrust1"/>
    <origin rpy="0 0 0" xyz="0 0 0"/>
    <axis xyz="0 0 1"/>
  </joint>
  <link name="thrust1">
    <inertial>
      <origin rpy="0 0 0" xyz="0 0 0"/>
      <mass value="0.0001"/>
      <inertia ixx="0.00001" ixy="0.0" ixz="0.0" iyy="0.00001" iyz="0.0" izz="0.00002"/>
    </inertial>
  </link>
  <joint name="edf1_left_mount" type="fixed">
    <child link="edf1_left"/>
    <parent link="gimbal1_pitch_module"/>
    <origin rpy="0 0 0" xyz="0 0.1115 0 "/>
    <axis xyz="0 0 1"/>
  </joint>
  <link name="edf1_left">
    <inertial>
      <origin rpy="0 0 0" xyz="0 0 0"/>
      <mass value="0.00001"/>
      <inertia ixx="0.000001" ixy="0.0" ixz="0.0" iyy="0.000001" iyz="0.0" izz="0.000002"/>
    </inertial>
  </link>
  <joint name="edf1_right_mount" type="fixed">
    <child link="edf1_right"/>
    <parent link="gimbal1_pitch_module"/>
    <origin rpy="0 0 0" xyz="0 -0.1115 0 "/>
    <axis xyz="0 0 1"/>
  </joint>
  <link name="edf1_right">
    <inertial>
      <origin rpy="0 0 0" xyz="0 0 0"/>
      <mass value="0.00001"/>
      <inertia ixx="0.000001" ixy="0.0" ixz="0.0" iyy="0.000001" iyz="0.0" izz="0.000002"/>
    </inertial>
  </link>
  <gazebo reference="thrust1">
    <dampingFactor>0.00</dampingFactor>
  </gazebo>
  <joint name="joint1_pitch" type="revolute">
    <limit effort="10.0" lower="-1.5707963267948966" upper="1.5707963267948966" velocity="0.1"/>
    <parent link="link1"/>
    <child link="inter_joint1"/>
    <origin rpy="0 0 0" xyz="0.424 0 0"/>
    <axis xyz="0 1 0"/>
    <dynamics damping="0.9" friction="0.05"/>
  </joint>
  <link name="inter_joint1">
    <inertial>
      <origin rpy="0 0 0" xyz="0.029179999999999998 -0.0042699999999999995 -0.0015500000000000002"/>
      <mass value="0.1329"/>
      <inertia ixx="0.0001" ixy="0" ixz="0.0" iyy="0.0001" iyz="0.0" izz="0.0001"/>
    </inertial>
    <visual>
      <origin rpy="0 0 0" xyz="0.02575 0 0"/>
      <geometry>
        <mesh filename="inter_joint_junction.stl"/>
      </geometry>
    </visual>
    <collision name="inter_joint1">
      <origin rpy="0 0 0" xyz="0.02575 0 0"/>
      <geometry>
        <mesh filename="inter_joint_junction.stl"/>
      </geometry>
    </collision>
  </link>
  <joint name="joint1_yaw" type="revolute">
    <limit effort="10.0" lower="-1.5707963267948966" upper="1.5707963267948966" velocity="0.1"/>
    <parent link="inter_joint1"/>
    <child link="link2"/>
    <origin rpy="0 0 0" xyz="0.0515 0 0"/>
    <axis xyz="0 0 1"/>
    <dynamics damping="0.9" friction="0.05"/>
  </joint>
  <gazebo reference="inter_joint1">
    <mu1>0.2</mu1>
    <mu2>0.2</mu2>
  </gazebo>
  <link name="root">
    <inertial>
      <origin rpy="0 0 0" xyz="0 0 0"/>
      <mass value="0.00001"/>
      <inertia ixx="0.000001" ixy="0.0" ixz="0.0" iyy="0.000001" iyz="0.0" izz="0.000002"/>
    </inertial>
  </link>
  <joint name="root_joint" type="fixed">
    <parent link="root"/>
    <child link="link1"/>
    <origin rpy="0 0 0" xyz="0 0 0"/>
    <axis xyz="0 0 1"/>
  </joint>
  <gazebo reference="link1">
    <mu1>0.4</mu1>
    <mu2>0.4</mu2>
  </gazebo>
  <link name="link2">
    <inertial>
      <origin rpy="0 0 0" xyz="0.22154 -0.00474 -0.01568"/>
      <mass value="1.1348"/>
      <inertia ixx="0.0018" ixy="-0.0009" ixz="-0.0006" iyy="0.0228" iyz="0.0001" izz="0.0219"/>
    </inertial>
    <visual>
      <origin rpy="0 0 0" xyz="0.212 0 0"/>
      <geometry>
        <mesh filename="ducted_fan_baselink.stl"/>
      </geometry>
    </visual>
    <collision name="link2">
      <origin rpy="0 0 0" xyz="0.212 0 0"/>
      <geometry>
        <mesh filename="ducted_fan_baselink.stl"/>
      </geometry>
    </collision>
  </link>
  <gazebo reference="link2">
    <dampingFactor>0.00</dampingFactor>
  </gazebo>
  <joint name="gimbal2_roll" type="revolute">
    <limit effort="3" lower="-3.14" upper="3.14" velocity="12.5"/>
    <parent link="link2"/>
    <child link="gimbal2_roll_module"/>
    <origin rpy="0 0 0" xyz="0.212 0 0"/>
    <axis xyz="1 0 0"/>
    <dynamics damping="0.1" friction="0.0"/>
  </joint>
  <link name="gimbal2_roll_module">
    <inertial>
      <origin rpy="0 0 0" xyz="-0.0276 0.00042 0.01548"/>
      <mass value="0.4604"/>
      <inertia ixx="0.0004" ixy="0" ixz="-0.0003" iyy="0.0004" iyz="0" izz="0.0003"/>
    </inertial>
    <visual>
      <origin rpy="0 0 0" xyz="-0.01 0 0"/>
      <geometry>
        <mesh filename="ducted_fan_gimbal_roll.stl"/>
      </geometry>
    </visual>
    <collision name="gimbal2_roll_module">
      <origin rpy="0 0 0" xyz="-0.01 0 0"/>
      <geometry>
        <mesh filename="ducted_fan_gimbal_roll.stl"/>
      </geometry>
    </collision>
  </link>
  <joint name="gimbal2_pitch" type="revolute">
    <limit effort="3" lower="-3.14" upper="3.14" velocity="12.5"/>
    <parent link="gimbal2_roll_module"/>
    <child link="gimbal2_pitch_module"/>
    <origin rpy="0 0 0" xyz="0 0 0.037"/>
    <axis xyz="0 1 0"/>
    <dynamics damping="0.1" friction="0.0"/>
  </joint>
  <link name="gimbal2_pitch_module">
    <inertial>
      <origin rpy="0 0 0" xyz="0 0.00033  -0.00871"/>
      <mass value="0.5301"/>
      <inertia ixx="0.0061" ixy="0.0" ixz="0.0" iyy="0.0001" iyz="0.0" izz="0.0061"/>
    </inertial>
    <visual>
      <origin rpy="0 0 0" xyz="0 0 0"/>
      <geometry>
        <mesh filename="ducted_fan_gimbal_pitch.stl"/>
      </geometry>
    </visual>
    <collision name="gimbal2_pitch_module">
      <origin rpy="0 0 0" xyz="0 0 0"/>
      <geometry>
        <mesh filename="ducted_fan_gimbal_pitch.stl"/>
      </geometry>
    </collision>
  </link>
  <joint name="rotor2" type="continuous">
    <limit effort="100.0" lower="2" upper="30" velocity="0.5"/>
    <parent link="gimbal2_pitch_module"/>
    <child link="thrust2"/>
    <origin rpy="0 0 0" xyz="0 0 0"/>
    <axis xyz="0 0 1"/>
  </joint>
  <link name="thrust2">
    <inertial>
      <origin rpy="0 0 0" xyz="0 0 0"/>
      <mass value="0.0001"/>
      <inertia ixx="0.00001" ixy="0.0" ixz="0.0" iyy="0.00001" iyz="0.0" izz="0.00002"/>
    </inertial>
  </link>
  <joint name="edf2_left_mount" type="fixed">
    <child link="edf2_left"/>
    <parent link="gimbal2_pitch_module"/>
    <origin rpy="0 0 0" xyz="0 0.1115 0 "/>
    <axis xyz="0 0 1"/>
  </joint>
  <link name="edf2_left">
    <inertial>
      <origin rpy="0 0 0" xyz="0 0 0"/>
      <mass value="0.00001"/>
      <inertia ixx="0.000001" ixy="0.0" ixz="0.0" iyy="0.000001" iyz="0.0" izz="0.000002"/>
    </inertial>
  </link>
  <joint name="edf2_right_mount" type="fixed">
    <child link="edf2_right"/>
    <parent link="gimbal2_pitch_module"/>
    <origin rpy="0 0 0" xyz="0 -0.1115 0 "/>
    <axis xyz="0 0 1"/>
  </joint>
  <link name="edf2_right">
    <inertial>
      <origin rpy="0 0 0" xyz="0 0 0"/>
      <mass value="0.00001"/>
      <inertia ixx="0.000001" ixy="0.0" ixz="0.0" iyy="0.000001" iyz="0.0" izz="0.000002"/>
    </inertial>
  </link>
  <gazebo reference="thrust2">
    <dampingFactor>0.00</dampingFactor>
  </gazebo>
  <joint name="joint2_pitch" type="revolute">
    <limit effort="10.0" lower="-1.5707963267948966" upper="1.5707963267948966" velocity="0.1"/>
    <parent link="link2"/>
    <child link="inter_joint2"/>
    <origin rpy="0 0 0" xyz="0.424 0 0"/>
    <axis xyz="0 1 0"/>
    <dynamics damping="0.9" friction="0.05"/>
  </joint>
  <link name="inter_joint2">
    <inertial>
      <origin rpy="0 0 0" xyz="0.029179999999999998 -0.0042699999999999995 -0.0015500000000000002"/>
      <mass value="0.1329"/>
      <inertia ixx="0.0001" ixy="0" ixz="0.0" iyy="0.0001" iyz="0.0" izz="0.0001"/>
    </inertial>
    <visual>
      <origin rpy="0 0 0" xyz="0.02575 0 0"/>
      <geometry>
        <mesh filename="inter_joint_junction.stl"/>
      </geometry>
    </visual>
    <collision name="inter_joint2">
      <origin rpy="0 0 0" xyz="0.02575 0 0"/>
      <geometry>
        <mesh filename="inter_joint_junction.stl"/>
      </geometry>
    </collision>
  </link>
  <joint name="joint2_yaw" type="revolute">
    <limit effort="10.0" lower="-1.5707963267948966" upper="1.5707963267948966" velocity="0.1"/>
    <parent link="inter_joint2"/>
    <child link="link3"/>
    <origin rpy="0 0 0" xyz="0.0515 0 0"/>
    <axis xyz="0 0 1"/>
    <dynamics damping="0.9" friction="0.05"/>
  </joint>
  <gazebo reference="inter_joint2">
    <mu1>0.2</mu1>
    <mu2>0.2</mu2>
  </gazebo>
  <link name="fc">
    <inertial>
      <origin rpy="0 0 0" xyz="0 0 0"/>
      <mass value="0.00001"/>
      <inertia ixx="0.000001" ixy="0.0" ixz="0.0" iyy="0.000001" iyz="0.0" izz="0.000002"/>
    </inertial>
  </link>
  <joint name="fc_joint" type="fixed">
    <child link="fc"/>
    <parent link="link2"/>
    <origin rpy="0 0 0" xyz="0.316 -0.004 0.043"/>
    <axis xyz="0 0 1"/>
  </joint>
  <gazebo reference="link2">
    <mu1>0.4</mu1>
    <mu2>0.4</mu2>
  </gazebo>
  <link name="link3">
    <inertial>
      <origin rpy="0 0 0" xyz="0.19922 -0.0058 -0.01695"/>
      <mass value="0.9289"/>
      <inertia ixx="0.0015" ixy="-0.0008" ixz="-0.0001" iyy="0.0198" iyz="0.0001" izz="0.0189"/>
    </inertial>
    <visual>
      <origin rpy="0 0 0" xyz="0.212 0 0"/>
      <geometry>
        <mesh filename="ducted_fan_general_link.stl"/>
      </geometry>
    </visual>
    <collision name="link3">
      <origin rpy="0 0 0" xyz="0.212 0 0"/>
      <geometry>
        <mesh filename="ducted_fan_general_link.stl"/>
      </geometry>
    </collision>
  </link>
  <gazebo reference="link3">
    <dampingFactor>0.00</dampingFactor>
  </gazebo>
  <joint name="gimbal3_roll" type="revolute">
    <limit effort="3" lower="-3.14" upper="3.14" velocity="12.5"/>
    <parent link="link3"/>
    <child link="gimbal3_roll_module"/>
    <origin rpy="0 0 0" xyz="0.212 0 0"/>
    <axis xyz="1 0 0"/>
    <dynamics damping="0.1" friction="0.0"/>
  </joint>
  <link name="gimbal3_roll_module">
    <inertial>
      <origin rpy="0 0 0" xyz="-0.0276 0.00042 0.01548"/>
      <mass value="0.4604"/>
      <inertia ixx="0.0004" ixy="0" ixz="-0.0003" iyy="0.0004" iyz="0" izz="0.0003"/>
    </inertial>
    <visual>
      <origin rpy="0 0 0" xyz="-0.01 0 0"/>
      <geometry>
        <mesh filename="ducted_fan_gimbal_roll.stl"/>
      </geometry>
    </visual>
    <collision name="gimbal3_roll_module">
      <origin rpy="0 0 0" xyz="-0.01 0 0"/>
      <geometry>
        <mesh filename="ducted_fan_gimbal_roll.stl"/>
      </geometry>
    </collision>
  </link>
  <joint name="gimbal3_pitch" type="revolute">
    <limit effort="3" lower="-3.14" upper="3.14" velocity="12.5"/>
    <parent link="gimbal3_roll_module"/>
    <child link="gimbal3_pitch_module"/>
    <origin rpy="0 0 0" xyz="0 0 0.037"/>
    <axis xyz="0 1 0"/>
    <dynamics damping="0.1" friction="0.0"/>
  </joint>
  <link name="gimbal3_pitch_module">
    <inertial>
      <origin rpy="0 0 0" xyz="0 0.00033  -0.00871"/>
      <mass value="0.5301"/>
      <inertia ixx="0.0061" ixy="0.0" ixz="0.0" iyy="0.0001" iyz="0.0" izz="0.0061"/>
    </inertial>
    <visual>
      <origin rpy="0 0 0" xyz="0 0 0"/>
      <geometry>
        <mesh filename="ducted_fan_gimbal_pitch.stl"/>
      </geometry>
    </visual>
    <collision name="gimbal3_pitch_module">
      <origin rpy="0 0 0" xyz="0 0 0"/>
      <geometry>
        <mesh filename="ducted_fan_gimbal_pitch.stl"/>
      </geometry>
    </collision>
  </link>
  <joint name="rotor3" type="continuous">
    <limit effort="100.0" lower="2" upper="30" velocity="0.5"/>
    <parent link="gimbal3_pitch_module"/>
    <child link="thrust3"/>
    <origin rpy="0 0 0" xyz="0 0 0"/>
    <axis xyz="0 0 1"/>
  </joint>
  <link name="thrust3">
    <inertial>
      <origin rpy="0 0 0" xyz="0 0 0"/>
      <mass value="0.0001"/>
      <inertia ixx="0.00001" ixy="0.0" ixz="0.0" iyy="0.00001" iyz="0.0" izz="0.00002"/>
    </inertial>
  </link>
  <joint name="edf3_left_mount" type="fixed">
    <child link="edf3_left"/>
    <parent link="gimbal3_pitch_module"/>
    <origin rpy="0 0 0" xyz="0 0.1115 0 "/>
    <axis xyz="0 0 1"/>
  </joint>
  <link name="edf3_left">
    <inertial>
      <origin rpy="0 0 0" xyz="0 0 0"/>
      <mass value="0.00001"/>
      <inertia ixx="0.000001" ixy="0.0" ixz="0.0" iyy="0.000001" iyz="0.0" izz="0.000002"/>
    </inertial>
  </link>
  <joint name="edf3_right_mount" type="fixed">
    <child link="edf3_right"/>
    <parent link="gimbal3_pitch_module"/>
    <origin rpy="0 0 0" xyz="0 -0.1115 0 "/>
    <axis xyz="0 0 1"/>
  </joint>
  <link name="edf3_right">
    <inertial>
      <origin rpy="0 0 0" xyz="0 0 0"/>
      <mass value="0.00001"/>
      <inertia ixx="0.000001" ixy="0.0" ixz="0.0" iyy="0.000001" iyz="0.0" izz="0.000002"/>
    </inertial>
  </link>
  <gazebo reference="thrust3">
    <dampingFactor>0.00</dampingFactor>
  </gazebo>
  <joint name="joint3_pitch" type="revolute">
    <limit effort="10.0" lower="-1.5707963267948966" upper="1.5707963267948966" velocity="0.1"/>
    <parent link="link3"/>
    <child link="inter_joint3"/>
    <origin rpy="0 0 0" xyz="0.424 0 0"/>
    <axis xyz="0 1 0"/>
    <dynamics damping="0.9" friction="0.05"/>
  </joint>
  <link name="inter_joint3">
    <inertial>
      <origin rpy="0 0 0" xyz="0.029179999999999998 -0.0042699999999999995 -0.0015500000000000002"/>
      <mass value="0.1329"/>
      <inertia ixx="0.0001" ixy="0" ixz="0.0" iyy="0.0001" iyz="0.0" izz="0.0001"/>
    </inertial>
    <visual>
      <origin rpy="0 0 0" xyz="0.02575 0 0"/>
      <geometry>
        <mesh filename="inter_joint_junction.stl"/>
      </geometry>
    </visual>
    <collision name="inter_joint3">
      <origin rpy="0 0 0" xyz="0.02575 0 0"/>
      <geometry>
        <mesh filename="inter_joint_junction.stl"/>
      </geometry>
    </collision>
  </link>
  <joint name="joint3_yaw" type="revolute">
    <limit effort="10.0" lower="-1.5707963267948966" upper="1.5707963267948966" velocity="0.1"/>
    <parent link="inter_joint3"/>
    <child link="link4"/>
    <origin rpy="0 0 0" xyz="0.0515 0 0"/>
    <axis xyz="0 0 1"/>
    <dynamics damping="0.9" friction="0.05"/>
  </joint>
  <gazebo reference="inter_joint3">
    <mu1>0.2</mu1>
    <mu2>0.2</mu2>
  </gazebo>
  <gazebo reference="link3">
    <mu1>0.4</mu1>
    <mu2>0.4</mu2>
  </gazebo>
  <link name="link4">
    <inertial>
      <origin rpy="0 0 0" xyz="0.16774 -0.00011 -0.02072"/>
      <mass value="0.7943"/>
      <inertia ixx="0.0012" ixy="0.0" ixz="0.0003" iyy="0.0145" iyz="0.0000" izz="0.0134"/>
    </inertial>
    <visual>
      <origin rpy="0 0 0" xyz="0.212 0 0"/>
      <geometry>
        <mesh filename="ducted_fan_end_link.stl"/>
      </geometry>
    </visual>
    <collision name="link4">
      <origin rpy="0 0 0" xyz="0.212 0 0"/>
      <geometry>
        <mesh filename="ducted_fan_end_link.stl"/>
      </geometry>
    </collision>
  </link>
  <gazebo reference="link4">
    <dampingFactor>0.00</dampingFactor>
  </gazebo>
  <joint name="gimbal4_roll" type="revolute">
    <limit effort="3" lower="-3.14" upper="3.14" velocity="12.5"/>
    <parent link="link4"/>
    <child link="gimbal4_roll_module"/>
    <origin rpy="0 0 0" xyz="0.212 0 0"/>
    <axis xyz="1 0 0"/>
    <dynamics damping="0.1" friction="0.0"/>
  </joint>
  <link name="gimbal4_roll_module">
    <inertial>
      <origin rpy="0 0 0" xyz="-0.0276 0.00042 0.01548"/>
      <mass value="0.4604"/>
      <inertia ixx="0.0004" ixy="0" ixz="-0.0003" iyy="0.0004" iyz="0" izz="0.0003"/>
    </inertial>
    <visual>
      <origin rpy="0 0 0" xyz="-0.01 0 0"/>
      <geometry>
        <mesh filename="ducted_fan_gimbal_roll.stl"/>
      </geometry>
    </visual>
    <collision name="gimbal4_roll_module">
      <origin rpy="0 0 0" xyz="-0.01 0 0"/>
      <geometry>
        <mesh filename="ducted_fan_gimbal_roll.stl"/>
      </geometry>
    </collision>
  </link>
  <joint name="gimbal4_pitch" type="revolute">
    <limit effort="3" lower="-3.14" upper="3.14" velocity="12.5"/>
    <parent link="gimbal4_roll_module"/>
    <child link="gimbal4_pitch_module"/>
    <origin rpy="0 0 0" xyz="0 0 0.037"/>
    <axis xyz="0 1 0"/>
    <dynamics damping="0.1" friction="0.0"/>
  </joint>
  <link name="gimbal4_pitch_module">
    <inertial>
      <origin rpy="0 0 0" xyz="0 0.00033  -0.00871"/>
      <mass value="0.5301"/>
      <inertia ixx="0.0061" ixy="0.0" ixz="0.0" iyy="0.0001" iyz="0.0" izz="0.0061"/>
    </inertial>
    <visual>
      <origin rpy="0 0 0" xyz="0 0 0"/>
      <geometry>
        <mesh filename="ducted_fan_gimbal_pitch.stl"/>
      </geometry>
    </visual>
    <collision name="gimbal4_pitch_module">
      <origin rpy="0 0 0" xyz="0 0 0"/>
      <geometry>
        <mesh filename="ducted_fan_gimbal_pitch.stl"/>
      </geometry>
    </collision>
  </link>
  <joint name="rotor4" type="continuous">
    <limit effort="100.0" lower="2" upper="30" velocity="0.5"/>
    <parent link="gimbal4_pitch_module"/>
    <child link="thrust4"/>
    <origin rpy="0 0 0" xyz="0 0 0"/>
    <axis xyz="0 0 1"/>
  </joint>
  <link name="thrust4">
    <inertial>
      <origin rpy="0 0 0" xyz="0 0 0"/>
      <mass value="0.0001"/>
      <inertia ixx="0.00001" ixy="0.0" ixz="0.0" iyy="0.00001" iyz="0.0" izz="0.00002"/>
    </inertial>
  </link>
  <joint name="edf4_left_mount" type="fixed">
    <child link="edf4_left"/>
    <parent link="gimbal4_pitch_module"/>
    <origin rpy="0 0 0" xyz="0 0.1115 0 "/>
    <axis xyz="0 0 1"/>
  </joint>
  <link name="edf4_left">
    <inertial>
      <origin rpy="0 0 0" xyz="0 0 0"/>
      <mass value="0.00001"/>
      <inertia ixx="0.000001" ixy="0.0" ixz="0.0" iyy="0.000001" iyz="0.0" izz="0.000002"/>
    </inertial>
  </link>
  <joint name="edf4_right_mount" type="fixed">
    <child link="edf4_right"/>
    <parent link="gimbal4_pitch_module"/>
    <origin rpy="0 0 0" xyz="0 -0.1115 0 "/>
    <axis xyz="0 0 1"/>
  </joint>
  <link name="edf4_right">
    <inertial>
      <origin rpy="0 0 0" xyz="0 0 0"/>
      <mass value="0.00001"/>
      <inertia ixx="0.000001" ixy="0.0" ixz="0.0" iyy="0.000001" iyz="0.0" izz="0.000002"/>
    </inertial>
  </link>
  <gazebo reference="thrust4">
    <dampingFactor>0.00</dampingFactor>
  </gazebo>
  <gazebo reference="link4">
    <mu1>0.4</mu1>
    <mu2>0.4</mu2>
  </gazebo>
  <mujoco>
    <compiler balanceinertia="true"/>
    <option/>
  </mujoco>
</robot>
